<?xml version="1.0" ?>
<robot name="cyberdog_description">
  <material name="black">
    <color rgba="0.0 0.0 0.0 1.0"/>
  </material>
  <material name="blue">
    <color rgba="0.0 0.0 0.8 1.0"/>
  </material>
  <material name="green">
    <color rgba="0.0 0.8 0.0 1.0"/>
  </material>
  <material name="grey">
    <color rgba="0.2 0.2 0.2 1.0"/>
  </material>
  <material name="silver">
    <color rgba="0.913725490196 0.913725490196 0.847058823529 1.0"/>
  </material>
  <material name="orange">
    <color rgba="1.0 0.423529411765 0.0392156862745 1.0"/>
  </material>
  <material name="brown">
    <color rgba="0.870588235294 0.811764705882 0.764705882353 1.0"/>
  </material>
  <material name="red">
    <color rgba="0.8 0.0 0.0 1.0"/>
  </material>
  <material name="white">
    <color rgba="1.0 1.0 1.0 1.0"/>
  </material>

  <!-- 悬挂 -->
  <!-- <link name="world"/>
  <joint name="base_static_joint" type="fixed">
      <origin rpy="0 0 0" xyz="0 0 0"/>
      <parent link="world"/>
      <child link="base"/>
  </joint> -->

  <link name="base">
    <visual>
      <origin rpy="0 0 0" xyz="0 0 0"/>
      <geometry>
        <box size="0.001 0.001 0.001"/>
      </geometry>
    </visual>
  </link>
  <joint name="floating_base" type="fixed">
    <origin rpy="0 0 0" xyz="0 0 0"/>
    <parent link="base"/>
    <child link="trunk"/>
  </joint>
  <link name="trunk">
    <inertial>
      <origin
        xyz="0 0 0"
        rpy="0 0 0" />
      <mass value="7.18" />
      <inertia
        ixx="0.032051"
        ixy="-0.00023217"
        ixz="0.002728"
        iyy="0.13707"
        iyz="5.6623E-05"
        izz="0.14946" />
    </inertial>
    <visual>
      <origin
        xyz="0 0 0"
        rpy="0 0 0" />
      <geometry>
        <mesh filename="../meshes/trunk.dae" />
      </geometry>
      <material name="">
        <color rgba="1 1 1 1" />
      </material>
    </visual>
    <collision>
      <origin
        xyz="0 0 0"
        rpy="0 0 0" />
      <geometry>
        <mesh filename="../meshes/trunk.STL" />
      </geometry>
    </collision>
  </link>

  <joint name="imu_joint" type="fixed">
    <parent link="trunk"/>
    <child link="imu_link"/>
    <origin rpy="0 0 0" xyz="0 0 0"/>
  </joint>
  <link name="imu_link">
    <!-- <inertial>
      <mass value="0.001"/>
      <origin rpy="0 0 0" xyz="0 0 0"/>
      <inertia ixx="0.0001" ixy="0" ixz="0" iyy="0.0001" iyz="0" izz="0.0001"/>
    </inertial>
    <visual>
      <origin rpy="0 0 0" xyz="0 0 0"/>
      <geometry>
        <box size="0.001 0.001 0.001"/>
      </geometry>
      <material name="red"/>
    </visual>
    <collision>
      <origin rpy="0 0 0" xyz="0 0 0"/>
      <geometry>
        <box size=".001 .001 .001"/>
      </geometry>
    </collision> -->
  </link>

  <link name="FR_hip">
    <inertial>
      <origin
        xyz="0 -0.053575 0"
        rpy="0 0 0" />
      <mass value="0.509" />
      <inertia
        ixx="0.00038097"
        ixy="1.2523E-05"
        ixz="-1.1653E-05"
        iyy="0.00069383"
        iyz="5.071E-06"
        izz="0.00047336" />
    </inertial>
    <visual>
      <origin
        xyz="0 0 0"
        rpy="0 0 0" />
      <geometry>
        <mesh filename="../meshes/hip_mirror.dae" />
      </geometry>
      <material name="">
        <color rgba="1 1 1 1" />
      </material>
    </visual>
    <collision>
      <origin
        xyz="0 0 0"
        rpy="0 0 0" />
      <geometry>
        <mesh filename="../meshes/hip_mirror.STL" />
      </geometry>
    </collision>
  </link>
  <joint name="FR_hip_joint"
    type="revolute">
    <origin
      xyz="0.23536 -0.05 0"
      rpy="0 0 0" />
    <parent link="trunk" />
    <child link="FR_hip" />
    <axis xyz="1 0 0" />
    <limit
      lower="-0.75"
      upper="0.75"
      effort="17"
      velocity="38.19" />
    <dynamics
      damping="0.0"
      friction="0.0" />
  </joint>
  <link name="FR_thigh">
    <inertial>
      <origin
        xyz="0 0 -0.1"
        rpy="0 0 0" />
      <mass value="0.664" />
      <inertia
        ixx="0.0033376"
        ixy="-7.1504E-07"
        ixz="-0.00019282"
        iyy="0.0026385"
        iyz="-9.3033E-06"
        izz="0.0013093" />
    </inertial>
    <visual>
      <origin
        xyz="0 0 0"
        rpy="0 0 0" />
      <geometry>
        <mesh filename="../meshes/thigh.dae" />
      </geometry>
      <material name="">
        <color rgba="1 1 1 1" />
      </material>
    </visual>
    <collision>
      <origin
        xyz="0 0 0"
        rpy="0 0 0" />
      <geometry>
        <mesh filename="../meshes/thigh.STL" />
      </geometry>
    </collision>
  </link>
  <joint name="FR_thigh_joint"
    type="revolute">
    <origin
      xyz="0 -0.10715 0"
      rpy="0 0 0" />
    <parent link="FR_hip" />
    <child link="FR_thigh" />
    <axis xyz="0 1 0" />
    <limit
      lower="-1.257"
      upper="4.363"
      effort="24"
      velocity="38.19" />
    <dynamics
      damping="0.0"
      friction="0.0" />
  </joint>
  <link name="FR_calf">
    <inertial>
      <origin
        xyz="0 0 -0.11439"
        rpy="0 0 0" />
      <mass value="0.114" />
      <inertia
        ixx="0.0014553"
        ixy="-3.2376E-08"
        ixz="8.3885E-05"
        iyy="0.0021522"
        iyz="5.1259E-07"
        izz="0.00070545" />
    </inertial>
    <visual>
      <origin
        xyz="0 0 0"
        rpy="0 0 0" />
      <geometry>
        <mesh filename="../meshes/calf.dae" />
      </geometry>
      <material name="">
        <color rgba="1 1 1 1" />
      </material>
    </visual>
    <collision>
      <origin
        xyz="0 0 0"
        rpy="0 0 0" />
      <geometry>
        <mesh filename="../meshes/calf.STL" />
      </geometry>
    </collision>
  </link>
  <joint name="FR_calf_joint"
    type="revolute">
    <origin
      xyz="0 0 -0.2"
      rpy="0 0 0" />
    <parent link="FR_thigh" />
    <child link="FR_calf" />
    <axis xyz="0 1 0" />
    <limit
      lower="-2.478"
      upper="-0.506"
      effort="24"
      velocity="38.19" />
    <dynamics
      damping="0.0"
      friction="0.0" />
  </joint>
  <joint name="FR_foot_fixed" type="fixed"  dont_collapse="true">
    <origin rpy="0 0 0" xyz="0 0 -0.217"/>
    <parent link="FR_calf"/>
    <child link="FR_foot"/>
  </joint>
  <link name="FR_foot">
    <visual>
      <origin rpy="0 0 0" xyz="0 0 0"/>
      <geometry>
        <sphere radius="0.025"/>
      </geometry>
      <material name="grey"/>
    </visual>
    <collision>
      <origin rpy="0 0 0" xyz="0 0 0"/>
      <geometry>
        <sphere radius="0.025"/>
      </geometry>
    </collision>
    <inertial>
      <mass value="0.026"/>
      <inertia ixx="0.0" ixy="0.0" ixz="0.0" iyy="0.0" iyz="0.0" izz="0.0"/>
    </inertial>
  </link>

  <link name="FL_hip">
    <inertial>
      <origin
        xyz="0 0.053575 0"
        rpy="0 0 0" />
      <mass value="0.509" />
      <inertia
        ixx="0.00038097"
        ixy="1.2523E-05"
        ixz="-1.1653E-05"
        iyy="0.00069383"
        iyz="5.071E-06"
        izz="0.00047336" />
    </inertial>
    <visual>
      <origin
        xyz="0 0 0"
        rpy="0 0 0" />
      <geometry>
        <mesh filename="../meshes/hip.dae" />
      </geometry>
      <material name="">
        <color rgba="1 1 1 1" />
      </material>
    </visual>
    <collision>
      <origin
        xyz="0 0 0"
        rpy="0 0 0" />
      <geometry>
        <mesh filename="../meshes/hip.STL" />
      </geometry>
    </collision>
  </link>
  <joint name="FL_hip_joint"
    type="revolute">
    <origin
      xyz="0.23536 0.05 0"
      rpy="0 0 0" />
    <parent link="trunk" />
    <child link="FL_hip" />
    <axis xyz="1 0 0" />
    <limit
      lower="-0.75"
      upper="0.75"
      effort="17"
      velocity="38.19" />
    <dynamics
      damping="0.0"
      friction="0.0" />
  </joint>
  <link name="FL_thigh">
    <inertial>
      <origin
        xyz="0 0 -0.1"
        rpy="0 0 0" />
      <mass value="0.664" />
      <inertia
        ixx="0.0033376"
        ixy="-7.150375E-07"
        ixz="-0.00019282"
        iyy="0.0026385"
        iyz="-9.3033E-06"
        izz="0.0013093" />
    </inertial>
    <visual>
      <origin
        xyz="0 0 0"
        rpy="0 0 0" />
      <geometry>
        <mesh filename="../meshes/thigh.dae" />
      </geometry>
      <material name="">
        <color rgba="1 1 1 1" />
      </material>
    </visual>
    <collision>
      <origin
        xyz="0 0 0"
        rpy="0 0 0" />
      <geometry>
        <mesh filename="../meshes/thigh.STL" />
      </geometry>
    </collision>
  </link>
  <joint name="FL_thigh_joint"
    type="revolute">
    <origin
      xyz="0 0.10715 0"
      rpy="0 0 0" />
    <parent link="FL_hip" />
    <child link="FL_thigh" />
    <axis xyz="0 1 0" />
    <limit
      lower="-1.257"
      upper="4.363"
      effort="24"
      velocity="38.19" />
    <dynamics
      damping="0.0"
      friction="0.0" />
  </joint>
  <link name="FL_calf">
    <inertial>
      <origin
        xyz="0 0 -0.11439"
        rpy="0 0 0" />
      <mass value="0.114" />
      <inertia
        ixx="0.0014553"
        ixy="-3.2376E-08"
        ixz="8.3885E-05"
        iyy="0.0021522"
        iyz="5.1259E-07"
        izz="0.00070545" />
    </inertial>
    <visual>
      <origin
        xyz="0 0 0"
        rpy="0 0 0" />
      <geometry>
        <mesh filename="../meshes/calf.dae" />
      </geometry>
      <material name="">
        <color rgba="1 1 1 1" />
      </material>
    </visual>
    <collision>
      <origin
        xyz="0 0 0"
        rpy="0 0 0" />
      <geometry>
        <mesh filename="../meshes/calf.STL" />
      </geometry>
    </collision>
  </link>
  <joint name="FL_calf_joint"
    type="revolute">
    <origin
      xyz="0 0 -0.2"
      rpy="0 0 0" />
    <parent link="FL_thigh" />
    <child link="FL_calf" />
    <axis xyz="0 1 0" />
    <limit
      lower="-2.478"
      upper="-0.506"
      effort="24"
      velocity="38.19" />
    <dynamics
      damping="0.0"
      friction="0.0" />
  </joint>
  <joint name="FL_foot_fixed" type="fixed" dont_collapse="true">
    <origin rpy="0 0 0" xyz="0 0 -0.217"/>
    <parent link="FL_calf"/>
    <child link="FL_foot"/>
  </joint>
  <link name="FL_foot">
    <visual>
      <origin rpy="0 0 0" xyz="0 0 0"/>
      <geometry>
        <sphere radius="0.025"/>
      </geometry>
      <material name="grey"/>
    </visual>
    <collision>
      <origin rpy="0 0 0" xyz="0 0 0"/>
      <geometry>
        <sphere radius="0.025"/>
      </geometry>
    </collision>
    <inertial>
      <mass value="0.026"/>
      <inertia ixx="0.0" ixy="0.0" ixz="0.0" iyy="0.0" iyz="0.0" izz="0.0"/>
    </inertial>
  </link>

  <link name="RR_hip">
    <inertial>
      <origin
        xyz="0 -0.053575 0"
        rpy="0 0 0" />
      <mass value="0.509" />
      <inertia
        ixx="0.00038097"
        ixy="1.2523E-05"
        ixz="-1.1653E-05"
        iyy="0.00069383"
        iyz="5.071E-06"
        izz="0.00047336" />
    </inertial>
    <visual>
      <origin
        xyz="0 0 0"
        rpy="0 0 0" />
      <geometry>
        <mesh filename="../meshes/hip_mirror.dae" />
      </geometry>
      <material name="">
        <color rgba="1 1 1 1" />
      </material>
    </visual>
    <collision>
      <origin
        xyz="0 0 0"
        rpy="0 0 0" />
      <geometry>
        <mesh filename="../meshes/hip_mirror.STL" />
      </geometry>
    </collision>
  </link>
  <joint name="RR_hip_joint"
    type="revolute">
    <origin
      xyz="-0.23536 -0.05 0"
      rpy="0 0 0" />
    <parent link="trunk" />
    <child link="RR_hip" />
    <axis xyz="1 0 0" />
    <limit
      lower="-0.75"
      upper="0.75"
      effort="17"
      velocity="38.19" />
    <dynamics
      damping="0.0"
      friction="0.0" />
  </joint>
  <link name="RR_thigh">
    <inertial>
      <origin
        xyz="0 0 -0.1"
        rpy="0 0 0" />
      <mass value="0.664" />
      <inertia
        ixx="0.0033376"
        ixy="-7.150375E-07"
        ixz="-0.00019282"
        iyy="0.0026385"
        iyz="-9.3033E-06"
        izz="0.0013093" />
    </inertial>
    <visual>
      <origin
        xyz="0 0 0"
        rpy="0 0 0" />
      <geometry>
        <mesh filename="../meshes/thigh.dae" />
      </geometry>
      <material name="">
        <color rgba="1 1 1 1" />
      </material>
    </visual>
    <collision>
      <origin
        xyz="0 0 0"
        rpy="0 0 0" />
      <geometry>
        <mesh filename="../meshes/thigh.STL" />
      </geometry>
    </collision>
  </link>
  <joint name="RR_thigh_joint"
    type="revolute">
    <origin
      xyz="0 -0.10715 0"
      rpy="0 0 0" />
    <parent link="RR_hip" />
    <child link="RR_thigh" />
    <axis xyz="0 1 0" />
    <limit
      lower="-2.01"
      upper="3.49"
      effort="24"
      velocity="38.19" />
    <dynamics
      damping="0.0"
      friction="0.0" />
  </joint>
  <link name="RR_calf">
    <inertial>
      <origin
        xyz="0 0 -0.11439"
        rpy="0 0 0" />
      <mass value="0.114" />
      <inertia
        ixx="0.0014553"
        ixy="-3.2376E-08"
        ixz="8.3885E-05"
        iyy="0.0021522"
        iyz="5.1259E-07"
        izz="0.00070545" />
    </inertial>
    <visual>
      <origin
        xyz="0 0 0"
        rpy="0 0 0" />
      <geometry>
        <mesh filename="../meshes/calf.dae" />
      </geometry>
      <material name="">
        <color rgba="1 1 1 1" />
      </material>
    </visual>
    <collision>
      <origin
        xyz="0 0 0"
        rpy="0 0 0" />
      <geometry>
        <mesh filename="../meshes/calf.STL" />
      </geometry>
    </collision>
  </link>
  <joint name="RR_calf_joint"
    type="revolute">
    <origin
      xyz="0 0 -0.2"
      rpy="0 0 0" />
    <parent link="RR_thigh" />
    <child link="RR_calf" />
    <axis xyz="0 1 0" />
    <limit
      lower="-2.478"
      upper="-0.506"
      effort="24"
      velocity="38.19" />
    <dynamics
      damping="0.0"
      friction="0.0" />
  </joint>
  <joint name="RR_foot_fixed" type="fixed" dont_collapse="true">
    <origin rpy="0 0 0" xyz="0 0 -0.217"/>
    <parent link="RR_calf"/>
    <child link="RR_foot"/>
  </joint>
  <link name="RR_foot">
    <visual>
      <origin rpy="0 0 0" xyz="0 0 0"/>
      <geometry>
        <sphere radius="0.025"/>
      </geometry>
      <material name="grey"/>
    </visual>
    <collision>
      <origin rpy="0 0 0" xyz="0 0 0"/>
      <geometry>
        <sphere radius="0.025"/>
      </geometry>
    </collision>
    <inertial>
      <mass value="0.026"/>
      <inertia ixx="0.0" ixy="0.0" ixz="0.0" iyy="0.0" iyz="0.0" izz="0.0"/>
    </inertial>
  </link>

  <link name="RL_hip">
    <inertial>
      <origin
        xyz="0 0.053575 0"
        rpy="0 0 0" />
      <mass value="0.509" />
      <inertia
        ixx="0.00038097"
        ixy="1.2523E-05"
        ixz="-1.1653E-05"
        iyy="0.00069383"
        iyz="5.071E-06"
        izz="0.00047336" />
    </inertial>
    <visual>
      <origin
        xyz="0 0 0"
        rpy="0 0 0" />
      <geometry>
        <mesh filename="../meshes/hip.dae" />
      </geometry>
      <material name="">
        <color rgba="1 1 1 1" />
      </material>
    </visual>
    <collision>
      <origin
        xyz="0 0 0"
        rpy="0 0 0" />
      <geometry>
        <mesh filename="../meshes/hip.STL" />
      </geometry>
    </collision>
  </link>
  <joint name="RL_hip_joint"
    type="revolute">
    <origin
      xyz="-0.23536 0.05 0"
      rpy="0 0 0" />
    <parent link="trunk" />
    <child link="RL_hip" />
    <axis xyz="1 0 0" />
    <limit
      lower="-0.75"
      upper="0.75"
      effort="17"
      velocity="38.19" />
    <dynamics
      damping="0.0"
      friction="0.0" />
  </joint>
  <link name="RL_thigh">
    <inertial>
      <origin
        xyz="0 0 -0.1"
        rpy="0 0 0" />
      <mass value="0.664" />
      <inertia
        ixx="0.0033376"
        ixy="-7.1504E-07"
        ixz="-0.00019282"
        iyy="0.0026385"
        iyz="-9.3033E-06"
        izz="0.0013093" />
    </inertial>
    <visual>
      <origin
        xyz="0 0 0"
        rpy="0 0 0" />
      <geometry>
        <mesh filename="../meshes/thigh.dae" />
      </geometry>
      <material name="">
        <color rgba="1 1 1 1" />
      </material>
    </visual>
    <collision>
      <origin
        xyz="0 0 0"
        rpy="0 0 0" />
      <geometry>
        <mesh filename="../meshes/thigh.STL" />
      </geometry>
    </collision>
  </link>
  <joint name="RL_thigh_joint"
    type="revolute">
    <origin
      xyz="0 0.10715 0"
      rpy="0 0 0" />
    <parent link="RL_hip" />
    <child link="RL_thigh" />
    <axis xyz="0 1 0" />
    <limit
      lower="-2.01"
      upper="3.49"
      effort="24"
      velocity="38.19" />
    <dynamics
      damping="0.0"
      friction="0.0" />
  </joint>
  <link name="RL_calf">
    <inertial>
      <origin
        xyz="0 0 -0.11439"
        rpy="0 0 0" />
      <mass value="0.114" />
      <inertia
        ixx="0.0014553"
        ixy="-3.2376E-08"
        ixz="8.3885E-05"
        iyy="0.0021522"
        iyz="5.1259E-07"
        izz="0.00070545" />
    </inertial>
    <visual>
      <origin
        xyz="0 0 0"
        rpy="0 0 0" />
      <geometry>
        <mesh filename="../meshes/calf.dae" />
      </geometry>
      <material name="">
        <color rgba="1 1 1 1" />
      </material>
    </visual>
    <collision>
      <origin
        xyz="0 0 0"
        rpy="0 0 0" />
      <geometry>
        <mesh filename="../meshes/calf.STL" />
      </geometry>
    </collision>
  </link>
  <joint name="RL_calf_joint"
    type="revolute">
    <origin
      xyz="0 0 -0.2"
      rpy="0 0 0" />
    <parent link="RL_thigh" />
    <child link="RL_calf" />
    <axis xyz="0 1 0" />
    <limit
      lower="-2.478"
      upper="-0.506"
      effort="24"
      velocity="38.19" />
    <dynamics
      damping="0.0"
      friction="0.0" />
  </joint>
  <joint name="RL_foot_fixed" type="fixed" dont_collapse="true">
    <origin rpy="0 0 0" xyz="0 0 -0.217"/>
    <parent link="RL_calf"/>
    <child link="RL_foot"/>
  </joint>
  <link name="RL_foot">
    <visual>
      <origin rpy="0 0 0" xyz="0 0 0"/>
      <geometry>
        <sphere radius="0.025"/>
      </geometry>
      <material name="grey"/>
    </visual>
    <collision>
      <origin rpy="0 0 0" xyz="0 0 0"/>
      <geometry>
        <sphere radius="0.025"/>
      </geometry>
    </collision>
    <inertial>
      <mass value="0.026"/>
      <inertia ixx="0.0" ixy="0.0" ixz="0.0" iyy="0.0" iyz="0.0" izz="0.0"/>
    </inertial>
  </link>

</robot>